Workbook

Sheet Cover
A2: APPLE INC.
A3: Three-Statement Financial Model + Valuation
A4: Source: Yahoo Finance (yfinance) | Figures in $M unless stated
A6: Color-Coding Legend
A7: Blue text | B7: Hardcoded input
A8: Black text | B8: Calculated formula
A9: Green text | B9: Cross-sheet link
A10: Light blue bg | B10: Key IS metric
A11: Light green bg | B11: Key BS metric
A12: Light amber bg | B12: Key CFS metric
A13: Light gray bg | B13: Subtotal / total
A15: Sheet Navigation
A16: Income Statement | B16: Revenue → COGS → Gross Profit → EBIT → Net Income
A17: Balance Sheet | B17: Assets = Liabilities + Equity
A18: Cash Flow Statement | B18: Operating / Investing / Financing
A19: 3-Stmt Linkage | B19: Side-by-side cross-statement ties
A20: DCF Model | B20: 5-Year UFCF projection + Terminal Value
A21: WACC Calculation | B21: CAPM cost of equity + after-tax cost of debt
A22: Trading Comps | B22: Peer EV/EBITDA, EV/Rev, P/E multiples
A23: Valuation Summary | B23: Football field — blended implied price

Sheet Income Statement
A1: APPLE INC. — INCOME STATEMENT
A2: Fiscal Year | $M
B3: 2025 | C3: % of Rev | D3: YoY Δ ($M) | E3: 2024 | F3: Notes
A4: REVENUE
A5: Total Net Revenue | B5: 416161 | C5: 1 | D5: 25126 | E5: 391035 | F5: Source: Yahoo Finance — Total Revenue
A6: COST OF GOODS SOLD
A7: Total COGS | B7: 220960 | C7: =B7/B5 | D7: 10608 | E7: 210352 | F7: Direct cost of goods sold; gross margin = 1 − COGS/Revenue
A8: GROSS PROFIT | B8: =B5-B7 | C8: =B8/B5 | D8: 14518 | E8: 180683 | F8: =Revenue − COGS; key profitability metric before operating expenses
A9: OPERATING EXPENSES
A10: Research & Development | B10: 34550 | C10: =B10/B5 | D10: 3180 | E10: 31370 | F10: Investment in future products, services, and technologies
A11: Selling, General & Administrative | B11: 27601 | C11: =B11/B5 | D11: 1504 | E11: 26097 | F11: Sales, marketing, and general & administrative overhead
A12: Total Operating Expenses | B12: =B10+B11 | C12: =B12/B5 | D12: =D10+D11 | E12: =E10+E11 | F12: =R&D + SG&A; total cash operating expenses below the gross profit line
A13: OPERATING INCOME (EBIT) | B13: =B8-B12 | C13: =B13/B5 | D13: 9834 | E13: 123216 | F13: =Gross Profit − OpEx; earnings before interest & tax; key driver of DCF
A14: BELOW-THE-LINE ITEMS
A15: Interest & Other Income, net | B15: -321 | C15: =B15/B5 | D15: -590 | E15: 269 | F15: Net interest income/(expense); large cash pile makes this positive for Apple
A16: Pre-Tax Income (EBT) | B16: =B13+B15 | C16: =B16/B5 | D16: =B16-E16 | E16: 123485 | F16: =EBIT + Net Interest; taxable income base before applying the effective tax rate
A17: Income Tax Expense | B17: -20719 | C17: =B17/B5 | D17: =B17-E17 | E17: -29749 | F17: Provision for income taxes; shown as negative (cash outflow to taxing authorities)
A18: Effective Tax Rate | B18: =ABS(B17)/B16 | E18: =ABS(E17)/E16
A19: NET INCOME | B19: =B16+B17 | C19: =B19/B5 | D19: 18274 | E19: 93736 | F19: ↓ Flows to Retained Earnings (BS) and CFS starting line
A21: EBITDA BRIDGE
A22: EBIT (Operating Income) | B22: =B13 | C22: =B22/B5 | D22: 9834 | E22: 123216
A23: Add: Depreciation & Amortisation | B23: 11698 | C23: =B23/B5 | D23: 253 | E23: 11445 | F23: Non-cash charge; reduces reported earnings but not a cash outflow
A24: EBITDA | B24: =B22+B23 | C24: =B24/B5 | D24: 10087 | E24: 134661 | F24: =EBIT + D&A; proxy for operating cash flow; used in EV/EBITDA valuation
A26: KEY METRICS
A27: Diluted Shares Outstanding (M) | B27: 14687.356 | F27: Diluted count includes vested options and unvested RSUs; source: Yahoo Finance
A28: Gross Margin % | B28: =B8/B5
A29: EBIT Margin % | B29: =B13/B5
A30: EBITDA Margin % | B30: =B24/B5
A31: Net Margin % | B31: =B19/B5

Sheet Balance Sheet
A1: APPLE INC. — BALANCE SHEET
A2: $M
B3: 2025 | C3: 2024 | D3: Change ($M) | E3: Notes
A4: ASSETS — CURRENT
A5: Cash and Cash Equivalents | B5: 35934 | C5: 29943 | D5: =B5-C5 | E5: Ties to CFS ending balance ↑
A6: Marketable Securities (short-term) | B6: 18763 | C6: 35228 | D6: =B6-C6 | E6: Short-term investment portfolio; liquid; part of Apple's capital return strategy
A7: Accounts Receivable, net | B7: 72957 | C7: 66243 | D7: =B7-C7 | E7: Amounts owed by customers; watch DSO trend for collection efficiency
A8: Inventories | B8: 5718 | C8: 7286 | D8: =B8-C8 | E8: Finished goods held for sale; Apple runs lean inventory (low days)
A9: Other Current Assets | B9: 14585 | C9: 14287 | D9: =B9-C9 | E9: Prepaid expenses, vendor non-trade receivables, and other short-term items
A10: Total Current Assets | B10: =SUM(B5:B9) | C10: =SUM(C5:C9) | D10: =B10-C10
A11: NON-CURRENT ASSETS
A12: Marketable Securities (long-term) | B12: 77723 | C12: 91479 | D12: =B12-C12 | E12: Long-term AFS portfolio at fair value; unrealized gains in OCI
A13: Property, Plant & Equipment, net | B13: 49834 | C13: 45680 | D13: =B13-C13 | E13: Gross PP&E less accumulated depreciation; CapEx increases, D&A decreases this
A14: Other Non-Current Assets | B14: 62950 | C14: 55335 | D14: =B14-C14 | E14: Deferred tax assets, intangibles, lease right-of-use assets, and other long-term items
A15: Total Non-Current Assets | B15: =SUM(B12:B14) | C15: =SUM(C12:C14) | D15: =B15-C15
A16: TOTAL ASSETS | B16: =B10+B15 | C16: =C10+C15 | D16: =B16-C16
A18: LIABILITIES — CURRENT
A19: Accounts Payable | B19: 82876 | C19: 95561 | D19: =B19-C19 | E19: Amounts owed to suppliers; rising AP is a source of cash (interest-free financing)
A20: Deferred Revenue (short-term) | B20: 9055 | C20: 8249 | D20: =B20-C20 | E20: Unearned service revenue (e.g. AppleCare, iCloud, App Store subscriptions)
A21: Current Portion of Long-Term Debt | B21: 20329 | C21: 20879 | D21: =B21-C21 | E21: LTD maturing within 12 months; monitor for refinancing needs
A22: Other Current Liabilities | B22: 44452 | C22: 44024 | D22: =B22-C22 | E22: Accrued expenses, taxes payable, and other short-term obligations
A23: Total Current Liabilities | B23: =SUM(B19:B22) | C23: =SUM(C19:C22) | D23: =B23-C23
A24: NON-CURRENT LIABILITIES
A25: Long-Term Debt | B25: 78328 | C25: 85750 | D25: =B25-C25 | E25: Bonds payable due > 1 year; Apple uses debt cheaply to fund buybacks and dividends
A26: Other Non-Current Liabilities | B26: 41549 | C26: 45888 | D26: =B26-C26 | E26: Long-term deferred tax liabilities, lease obligations, and other long-dated obligations
A27: Total Non-Current Liabilities | B27: =SUM(B25:B26) | C27: =SUM(C25:C26) | D27: =B27-C27
A28: TOTAL LIABILITIES | B28: =B23+B27 | C28: =C23+C27 | D28: =B28-C28
A30: SHAREHOLDERS' EQUITY
A31: Common Stock & APIC | B31: 73733 | C31: 56950 | D31: =B31-C31 | E31: Par value + additional paid-in capital; reduced by share buybacks over time
A32: Retained Earnings | B32: -14264 | C32: -19154 | D32: =B32-C32 | E32: Links: Prior RE + Net Income – Dividends; accumulates lifetime earnings
A33: Accumulated OCI | B33: -5571 | C33: -7172 | D33: =B33-C33 | E33: Unrealized gains/losses on AFS securities and hedging instruments
A34: TOTAL SHAREHOLDERS' EQUITY | B34: =SUM(B31:B33) | C34: =SUM(C31:C33) | D34: =B34-C34
A36: TOTAL LIABILITIES + EQUITY | B36: =B28+B34 | C36: =C28+C34
A37: Balance Check (Assets – L+E) | B37: =B16-B36 | E37: Should be $0 / "✓ BALANCED"

Sheet Cash Flow Statement
A1: APPLE INC. — CASH FLOW STATEMENT
A2: $M | Indirect Method
B3: 2025 | C3: 2024 | D3: Change ($M) | E3: Notes
A4: SECTION 1: OPERATING ACTIVITIES
A5: Net Income (from Income Statement) | B5: 112010 | C5: 93736 | D5: =B5-C5 | E5: ↑ Links FROM Income Statement
A6: + Depreciation & Amortisation | B6: 11698 | C6: 11445 | D6: =B6-C6 | E6: Non-cash charge; reduces IS earnings but not a cash outflow — added back here
A7: + Stock-Based Compensation | B7: 12863 | C7: 11688 | D7: =B7-C7 | E7: Non-cash equity comp expense; dilutes shareholders but has no cash impact
A8: Working Capital & Other Changes | B8: -25000 | C8: 3651 | D8: =B8-C8
A9: CASH FROM OPERATING ACTIVITIES | B9: 111482 | C9: 118254 | D9: =B9-C9
A11: SECTION 2: INVESTING ACTIVITIES
A12: – Capital Expenditure (CapEx) | B12: -12715 | C12: -9447 | D12: =B12-C12 | E12: Investment in PP&E; ties to PP&E on BS; FCF = Operating CF − CapEx
A13: Other Investing Activities (net) | B13: 27910 | C13: 12382 | D13: =B13-C13 | E13: Net proceeds from securities purchases/sales and other investing items
A14: CASH FROM INVESTING ACTIVITIES | B14: =B12+B13 | C14: 2935 | D14: =B14-C14
A16: SECTION 3: FINANCING ACTIVITIES
A17: – Dividends Paid | B17: -15421 | C17: -15234 | D17: =B17-C17 | E17: Cash returned to shareholders via regular quarterly dividend
A18: – Repurchase of Common Stock (Buybacks) | B18: -90711 | C18: -94949 | D18: =B18-C18 | E18: Capital return via buybacks; reduces share count and boosts EPS over time
A19: Other Financing Activities (net) | B19: -14554 | C19: -11800 | D19: =B19-C19 | E19: Net debt issuance/repayment and other financing items
A20: CASH FROM FINANCING ACTIVITIES | B20: =B17+B18+B19 | C20: -121983 | D20: =B20-C20
A22: NET INCREASE / (DECREASE) IN CASH | B22: =B9+B14+B20 | C22: =C9+C14+C20 | D22: =B22-C22
A23: Beginning Cash Balance | B23: 29943 | C23: 29965 | D23: =B23-C23
A24: ENDING CASH BALANCE | B24: =B22+B23 | C24: 29943 | D24: =B24-C24 | E24: ↑ Must match Cash on Balance Sheet — KEY LINKAGE
A26: FREE CASH FLOW BRIDGE
A27: Cash from Operating Activities | B27: =B9 | C27: =C9 | D27: =D9
A28: Less: Capital Expenditure | B28: =B12 | C28: =C12 | D28: =D12
A29: FREE CASH FLOW | B29: =B27+B28 | C29: =C27+C28 | D29: =B29-C29 | E29: =Operating CF − CapEx; true cash generation available to debt & equity holders
A30: FCF Margin % | B30: =B29/'Income Statement'!B5 | C30: =C29/'Income Statement'!E5 | D30: =B30-C30 | E30: FCF as % of revenue; links to Total Net Revenue on Income Statement

Sheet 3-Stmt Linkage
A1: THREE-STATEMENT LINKAGE
A3: INCOME STATEMENT | B3: $M | D3: BALANCE SHEET | E3: $M | G3: CASH FLOW STMT | H3: $M | I3: LINKAGE NOTE
A4: Revenue | B4: ='Income Statement'!B5 | C4: → | D4: Accounts Receivable | E4: ='Balance Sheet'!B7 | F4: → | G4: Net Income (start) | H4: ='Cash Flow Statement'!B5 | I4: LINK 1: Net income ties IS → CFS starting point
A5: COGS | B5: ='Income Statement'!B7 | C5: → | D5: Inventories | E5: ='Balance Sheet'!B8 | F5: → | G5: + D&A add-back | H5: ='Cash Flow Statement'!B6 | I5: LINK 2: D&A reduces IS earnings, added back on CFS
A6: Gross Profit | B6: ='Income Statement'!B8 | C6: → | D6: PP&E, net | E6: ='Balance Sheet'!B13 | F6: → | G6: – CapEx | H6: ='Cash Flow Statement'!B12 | I6: LINK 3: CapEx builds PP&E; D&A reduces PP&E
A7: R&D Expense | B7: ='Income Statement'!B10 | C7: → | D7: Total Assets | E7: ='Balance Sheet'!B16 | F7: → | G7: Working Capital Chgs | H7: ='Cash Flow Statement'!B8 | I7: LINK 4: WC changes bridge IS accruals to CFS cash
A8: EBIT | B8: ='Income Statement'!B13 | C8: → | D8: Accounts Payable | E8: ='Balance Sheet'!B19 | F8: → | G8: – WC & Other Adj. | H8: ='Cash Flow Statement'!B8 | I8: LINK 5: AP on BS links to WC adjustments on CFS
A9: Net Income | B9: ='Income Statement'!B19 | C9: → | D9: Retained Earnings | E9: ='Balance Sheet'!B32 | F9: → | G9: Ending Cash | H9: ='Cash Flow Statement'!B24 | I9: LINK 6: Net income → RE on BS; Ending cash ties CFS → BS
A10: EBITDA | B10: ='Income Statement'!B24 | C10: → | D10: Total Liabilities+Eq | E10: ='Balance Sheet'!B36 | F10: → | G10: Free Cash Flow | H10: ='Cash Flow Statement'!B29 | I10: LINK 7: EBITDA drives DCF; FCF = Operating CF – CapEx
A12: The Three Permanent Rules
A13: Rule 1: Net Income (IS) → ALWAYS flows to Retained Earnings (BS) and is the CFS starting point
A14: Rule 2: Ending Cash on CFS → ALWAYS equals Cash & Equivalents on the Balance Sheet
A15: Rule 3: Total Assets (BS) → ALWAYS equals Total Liabilities + Shareholders' Equity

Sheet DCF Model
A1: APPLE INC. — DCF MODEL | 5-Year Projection + Terminal Value
A2: $M unless stated
A3: Line Item | B3: Base | C3: FY+1E | D3: FY+2E | E3: FY+3E | F3: FY+4E | G3: FY+5E | H3: Terminal Value | I3: Notes
A4: KEY ASSUMPTIONS (blue = change for scenarios)
A5: Revenue Growth Rate | C5: 0.05 | D5: 0.07 | E5: 0.08 | F5: 0.08 | G5: 0.06
A6: EBIT Margin | B6: 0.32275 | C6: 0.3 | D6: 0.3 | E6: 0.3 | F6: 0.3 | G6: 0.3
A7: Tax Rate | B7: 0.21 | C7: 0.21 | D7: 0.21 | E7: 0.21 | F7: 0.21 | G7: 0.21
A8: D&A as % of Revenue | B8: 0.03 | C8: 0.03 | D8: 0.03 | E8: 0.03 | F8: 0.03 | G8: 0.03
A9: CapEx as % of Revenue | B9: 0.03 | C9: 0.03 | D9: 0.03 | E9: 0.03 | F9: 0.03 | G9: 0.03
A10: Change in NWC as % of Rev | B10: 0.005 | C10: 0.005 | D10: 0.005 | E10: 0.005 | F10: 0.005 | G10: 0.005
A11: WACC (Discount Rate) | B11: ='WACC Calculation'!B25
A12: Terminal Growth Rate (g) | B12: 0.025
A13: Exit Multiple (EV/EBITDA ×) | H13: 20
A15: STEP 1: PROJECT UNLEVERED FREE CASH FLOWS
A16: Revenue ($M) | B16: 451442.02 | C16: =B16*(1+C5) | D16: =C16*(1+D5) | E16: =D16*(1+E5) | F16: =E16*(1+F5) | G16: =F16*(1+G5) | I16: Base = last reported revenue; forecast years grow at assumed rate above
A17: EBIT ($M) | B17: =B16*B6 | C17: =C16*C6 | D17: =D16*D6 | E17: =E16*E6 | F17: =F16*F6 | G17: =G16*G6 | I17: =Revenue × EBIT Margin; operating profit before interest & tax
A18: NOPAT = EBIT × (1 – Tax Rate) | B18: =B17*(1-B7) | C18: =C17*(1-C7) | D18: =D17*(1-D7) | E18: =E17*(1-E7) | F18: =F17*(1-F7) | G18: =G17*(1-G7) | I18: Net Operating Profit After Tax; removes financing effects for unlevered view
A19: Add: D&A ($M) | B19: =B16*B8 | C19: =C16*C8 | D19: =D16*D8 | E19: =E16*E8 | F19: =F16*F8 | G19: =G16*G8 | I19: Non-cash charge added back; reduces IS earnings but not a cash outflow
A20: Less: CapEx ($M) | B20: =-B16*B9 | C20: =-C16*C9 | D20: =-D16*D9 | E20: =-E16*E9 | F20: =-F16*F9 | G20: =-G16*G9 | I20: Capital expenditure; shown negative (cash outflow to build/maintain assets)
A21: Less: Change in NWC ($M) | C21: =-(C16-B16)*C10 | D21: =-(D16-C16)*D10 | E21: =-(E16-D16)*E10 | F21: =-(F16-E16)*F10 | G21: =-(G16-F16)*G10 | I21: Incremental working capital needed as business grows; negative = cash used
A22: UNLEVERED FREE CASH FLOW | C22: =C18+C19+C20+C21 | D22: =D18+D19+D20+D21 | E22: =E18+E19+E20+E21 | F22: =F18+F19+F20+F21 | G22: =G18+G19+G20+G21 | I22: =NOPAT + D&A − CapEx − ΔNWC; pre-financing cash available to all capital providers
A24: STEP 2: TERMINAL VALUE (Gordon Growth Model)
A25: TV = Final UFCF × (1+g) / (WACC – g) | B25: =G22*(1+B12)/(B11-B12) | I25: Gordon Growth Model; WACC must exceed g or result is undefined — adjust assumptions if negative
A27: STEP 2B: TERMINAL VALUE (Exit Multiple Method — EV/EBITDA)
A28: Year 5 EBITDA = EBIT + D&A | B28: =G17+G19 | I28: Year 5 projected EBIT + D&A from assumptions above; exit multiple applied to this
A29: EV/EBITDA Exit Multiple | B29: =H13 | I29: From assumption table above (col H); update based on peer median in Trading Comps
A30: TV = Year 5 EBITDA × Exit Multiple | B30: =B28*B29 | I30: EV at Year 5 using market-based multiple; alternative to perpetuity growth (GGM)
A32: STEP 3: DISCOUNT TO PRESENT VALUE
A33: Year Number | C33: 1 | D33: 2 | E33: 3 | F33: 4 | G33: 5
A34: PV Discount Factor = 1 / (1+WACC)^n | C34: =1/(1+$B$11)^C33 | D34: =1/(1+$B$11)^D33 | E34: =1/(1+$B$11)^E33 | F34: =1/(1+$B$11)^F33 | G34: =1/(1+$B$11)^G33
A35: PV of Each UFCF | C35: =C22*C34 | D35: =D22*D34 | E35: =E22*E34 | F35: =F22*F34 | G35: =G22*G34
A36: PV of Terminal Value (GGM) | B36: =B25/(1+$B$11)^5 | I36: GGM Terminal Value discounted back 5 years at WACC; typically 60-80% of total EV
A37: PV of Terminal Value (Exit Multiple) | B37: =B30/(1+$B$11)^5 | I37: Exit Multiple TV discounted back 5 years at WACC
A39: STEP 4: BRIDGE TO EQUITY VALUE PER SHARE
A40: Sum of PV of UFCFs (Years 1–5) | B40: =SUM(C35:G35)
A41: PV of Terminal Value | B41: =B36
A42: TV as % of Total EV | B42: =B41/(B40+B41)
A43: ENTERPRISE VALUE (DCF) | B43: =B40+B41 | I43: =PV of FCFs + PV of Terminal Value; value of the whole enterprise (debt + equity)
A44: Add: Cash & Equivalents ($M) | B44: 68507.001 | I44: Cash is non-operating; added back to convert EV → Equity Value
A45: Less: Total Debt ($M) | B45: -84710.998 | I45: Debt holders have prior claim; deducted to get equity holders' value
...

Sheet WACC Calculation
A1: WACC CALCULATION — APPLE INC.
A2: WACC = (E/V)×Re + (D/V)×Rd×(1-T)
A3: Component | B3: Value | C3: Formula / Source | D3: Notes
A4: CAPITAL STRUCTURE (Market Value Weights)
A5: Market Cap / Equity Value ($M) | B5: 4532958.9 | C5: Share price × diluted shares | D5: Use market value, not book value
A6: Total Debt ($M) | B6: 84710.998 | C6: ST + LT debt from Balance Sheet | D6: Source: Yahoo Finance
A7: Total Capital (V = E + D) | B7: =B5+B6
A8: Equity Weight (E/V) | B8: =B5/B7
A9: Debt Weight (D/V) | B9: =B6/B7
A11: COST OF EQUITY — CAPM: Re = Rf + β × (Rm-Rf)
A12: Risk-Free Rate (Rf) | B12: 0.045 | C12: 10-year US Treasury yield
A13: Equity Risk Premium (ERP) | B13: 0.055 | C13: Damodaran implied ERP
A14: Beta (Blume-Adjusted, Levered β) | B14: 1.1172 | C14: Blume adj: ⅔×1.1759 + ⅓×1.0 = 1.1172 | Raw OLS derived: 1.1759
A15: Cost of Equity (Re) | B15: =B12+B14*B13
A17: COST OF DEBT
A18: Pre-Tax Cost of Debt (Rd) | B18: 0.05 | C18: Yield on outstanding bonds
A19: Tax Rate | B19: 0.21 | C19: Effective tax rate — Source: Yahoo Finance
A20: After-Tax Cost of Debt = Rd × (1-T) | B20: =B18*(1-B19)
A22: WACC CALCULATION
A23: Equity Component: (E/V) × Re | B23: =B8*B15
A24: Debt Component: (D/V) × Rd × (1-T) | B24: =B9*B20
A25: WACC = (E/V)×Re + (D/V)×Rd×(1-T) | B25: =B23+B24 | D25: Links to DCF Model assumptions
A27: BETA DERIVATION — STEP-BY-STEP (OLS Regression, 5Y Weekly vs S&P 500)
A28: Step | B28: Value | C28: Formula / Source | D28: Notes
A29: SETUP
A30: Regression Period | B30: 5 Years | C30: 5Y weekly (Fri-to-Fri) price returns | D30: 5Y window balances recency vs statistical robustness
A31: Benchmark | B31: S&P 500 (^GSPC) | C31: Standard US equity market proxy | D31: Used as the market portfolio in CAPM
A32: Observations (N) | B32: 261 | C32: Weekly return pairs aligned on common trading dates
A34: STEP 1 — RETURN STATISTICS
A35: Avg weekly return — Stock | B35: 0.003847 | C35: Mean of 261 weekly returns | D35: Simple arithmetic mean of weekly percentage returns
A36: Avg weekly return — S&P 500 | B36: 0.00233 | C36: Mean of 261 weekly S&P 500 returns
A37: Std dev — Stock weekly returns | B37: 0.03786 | C37: σ_stock = 3.7860% | D37: Measures total volatility of the stock's weekly returns
A38: Std dev — S&P 500 weekly returns | B38: 0.022476 | C38: σ_mkt = 2.2476% | D38: Measures total volatility of the market's weekly returns
A40: STEP 2 — COVARIANCE & VARIANCE
A41: Cov(Stock, S&P 500) | B41: 0.00059403 | C41: Cov = E[(r_stock − μ_stock)(r_mkt − μ_mkt)] | D41: How much stock & market returns move together; higher = more correlated
A42: Var(S&P 500) | B42: 0.00050518 | C42: Var = E[(r_mkt − μ_mkt)²] = σ_mkt² | D42: Market's own return variance; normalises the covariance to give beta
A44: STEP 3 — RAW BETA = Cov / Var
A45: Raw Beta (OLS slope) | B45: 1.1759 | C45: =0.00059403 / 0.00050518 | D45: OLS regression slope; how much the stock moves per 1% market move
A46: R-Squared (R²) | B46: 0.4873 | C46: R² = Corr(r_stock, r_mkt)² | D46: % of stock return variance explained by market; remainder is idiosyncratic risk
A48: STEP 4 — BLUME ADJUSTMENT = ⅔ × Raw Beta + ⅓ × 1.0
...

Sheet Trading Comps
A1: TRADING COMPARABLES — APPLE INC.
A2: Figures in $M | Prices approximate
A3: Company | B3: Ticker | C3: Mkt Cap | D3: + Debt | E3: – Cash | F3: Ent. Value | G3: Revenue | H3: EBITDA | I3: EV/Rev | J3: EV/EBITDA | K3: P/E | L3: Notes
A4: Apple Inc. | B4: AAPL | C4: 4532958.9 | D4: 84710.998 | E4: -68507.001 | F4: 4549162.9 | G4: 451442.02 | H4: 159976 | I4: =F4/G4 | J4: =F4/H4 | K4: 37.319225 | M4: Subject company
A5: Microsoft Corp. | B5: MSFT | C5: 2900729.5 | D5: 125432 | E5: -78228 | F5: 2947933.5 | G5: 318273 | H5: 184457 | I5: =F5/G5 | J5: =F5/H5 | K5: 23.26 | M5: Source: Yahoo Finance
A6: Alphabet Inc. | B6: GOOGL | C6: 4391827.9 | D6: 95876 | E6: -126840 | F6: 4360863.9 | G6: 422498.01 | H6: 161316 | I6: =F6/G6 | J6: =F6/H6 | K6: 27.47 | M6: Source: Yahoo Finance
A7: Meta Platforms | B7: META | C7: 1479647 | D7: 86769 | E7: -81180 | F7: 1485236 | G7: 214963 | H7: 109308 | I7: =F7/G7 | J7: =F7/H7 | K7: 21.18 | M7: Source: Yahoo Finance
A8: Amazon.com | B8: AMZN | C8: 2610427.9 | D8: 235540 | E8: -143088.99 | F8: 2702878.9 | G8: 742775.98 | H8: 155860.99 | I8: =F8/G8 | J8: =F8/H8 | K8: 31.76 | M8: Source: Yahoo Finance
A9: NVIDIA Corp. | B9: NVDA | C9: 4718977.3 | D9: 12814 | E9: -53172 | F9: 4678619.3 | G9: 253491 | H9: 165514 | I9: =F9/G9 | J9: =F9/H9 | K9: 29.88 | M9: Source: Yahoo Finance
A11: Peer Mean | I11: =AVERAGE(I5:I9) | J11: =AVERAGE(J5:J9) | K11: =AVERAGE(K5:K9)
A12: Peer Median | I12: =MEDIAN(I5:I9) | J12: =MEDIAN(J5:J9) | K12: =MEDIAN(K5:K9)
A14: IMPLIED VALUATION (applying peer median multiples to subject)
A15: Implied EV (Peer Median EV/EBITDA × Subject EBITDA) | B15: =J12*H4
A16: Bridge: – Debt + Cash | B16: =B15-D4+E4
A17: Diluted Shares (M) | B17: 14687.356
A18: Implied Share Price (Comps-based) | B18: =B16/B17

Sheet Valuation Summary
A1: VALUATION SUMMARY — FOOTBALL FIELD | APPLE INC.
A2: Implied Share Price Ranges Across Methodologies
A3: Methodology | B3: Low | C3: Base Case | D3: High | E3: Metric | F3: Weight | G3: Notes
A4: 52-Week Trading Range | B4: 201.5 | C4: 308.63 | D4: 317.4 | E4: Share price | F4: 0 | G4: Market anchor — not intrinsic value
A5: DCF — Base Case | B5: 262.3355 | C5: 320.9752 | D5: 385.7875 | E5: UFCF + TV | F5: 0.35 | G5: WACC & terminal growth assumptions — see DCF sheet
A6: Trading Comps — EV/EBITDA | B6: 277.767 | C6: 308.63 | D6: 354.9245 | E6: LTM EBITDA | F6: 0.25 | G6: Peer median multiple applied to subject EBITDA
A7: Trading Comps — P/E | B7: 283.9396 | C7: 320.9752 | D7: 364.1834 | E7: LTM EPS | F7: 0.25 | G7: Peer P/E range applied to subject EPS
A8: Precedent Transactions | B8: 324.0615 | C8: 370.356 | D8: 432.082 | E8: LTM EBITDA | F8: 0.15 | G8: Control premium ~25-35% vs. trading comps
A9: Analyst Price Targets | B9: 215 | C9: 315.09048 | D9: 400 | E9: Consensus | F9: 0 | G9: Wall Street 12-month PT consensus
A11: Weighted Average Implied Price | C11: =SUMPRODUCT(C4:C9,F4:F9) | G11: SUMPRODUCT of Base Case × Weight; weights in col F must sum to 100%
A12: Actual Market Price | C12: 308.63 | G12: Source: Yahoo Finance — AAPL close
A14: METHODOLOGY COMPARISON
A15: Method | B15: Pros | C15: Cons | D15: Best Use Case
A16: DCF | B16: Intrinsic; captures unique characteristics | C16: Sensitive to WACC & g; needs detailed forecasts | D16: Standalone; stable FCF companies
A17: Trading Comps | B17: Live market sentiment; easy to update | C17: Market can misprice; peers may differ | D17: Quick benchmarking; IPO pricing
A18: Precedent Transactions | B18: Includes control premium; real deal economics | C18: Historical; market conditions change | D18: M&A advisory; fairness opinions
A19: LBO Analysis | B19: Sets floor for PE buyers; leverage capacity | C19: Irrelevant for strategic buyers | D19: Sponsored / PE deals
A20: Sum-of-Parts (SOTP) | B20: Values conglomerates properly by segment | C20: Complex; needs separate comps per segment | D20: Conglomerates; multi-segment cos
